<?xml version="1.0" ?>
<!-- =================================================================================== -->
<!-- |    This document was autogenerated by xacro from src/ackermann_robot/urdf/ackermann_robot.xacro | -->
<!-- |    EDITING THIS FILE BY HAND IS NOT RECOMMENDED                                 | -->
<!-- =================================================================================== -->
<robot name="ackermann_robot">
  <!-- ===================== -->
  <!-- Real hardware values  -->
  <!-- ===================== -->
  <!-- Materials -->
  <material name="chassis_red">
    <color rgba="1.0 0.0 0.0 1"/>
  </material>
  <material name="wheel_black">
    <color rgba="0.05 0.05 0.05 1"/>
  </material>
  <!-- ===================== -->
  <!-- Base frame            -->
  <!-- ===================== -->
  <!-- Robot center reference -->
  <link name="base_link"/>
  <!-- ===================== -->
  <!-- Chassis               -->
  <!-- ===================== -->
  <link name="chassis_link">
    <inertial>
      <origin xyz="0 0 0"/>
      <mass value="0.13442"/>
      <inertia ixx="1.50903123e-04" ixy="4.70052075e-08" ixz="6.59784866e-15" iyy="8.14177826e-04" iyz="1.01460270e-15" izz="9.64991335e-04"/>
    </inertial>
    <!-- Bottom plate -->
    <visual>
      <origin rpy="0 0 0" xyz="0 0 0.037"/>
      <geometry>
        <mesh filename="/home/mohana/robot_ws/src/ackermann_robot/meshes/chassis_visual.stl" scale="0.001 0.001 0.001"/>
      </geometry>
      <material name="chassis_red"/>
    </visual>
    <!-- Top plate -->
    <visual>
      <origin rpy="0 0 0" xyz="0 0 0.079"/>
      <geometry>
        <mesh filename="/home/mohana/robot_ws/src/ackermann_robot/meshes/chassis_visual.stl" scale="0.001 0.001 0.001"/>
      </geometry>
      <material name="chassis_red"/>
    </visual>
    <!-- Front left standoff -->
    <visual>
      <origin rpy="0 0 0" xyz="0.115 0.040249999999999994 0.057999999999999996"/>
      <geometry>
        <cylinder length="0.04" radius="0.004"/>
      </geometry>
      <material name="wheel_black"/>
    </visual>
    <!-- Front right -->
    <visual>
      <origin rpy="0 0 0" xyz="0.115 -0.040249999999999994 0.057999999999999996"/>
      <geometry>
        <cylinder length="0.04" radius="0.004"/>
      </geometry>
      <material name="wheel_black"/>
    </visual>
    <!-- Rear left -->
    <visual>
      <origin rpy="0 0 0" xyz="-0.115 0.040249999999999994 0.057999999999999996"/>
      <geometry>
        <cylinder length="0.04" radius="0.004"/>
      </geometry>
      <material name="wheel_black"/>
    </visual>
    <!-- Rear right -->
    <visual>
      <origin rpy="0 0 0" xyz="-0.115 -0.040249999999999994 0.057999999999999996"/>
      <geometry>
        <cylinder length="0.04" radius="0.004"/>
      </geometry>
      <material name="wheel_black"/>
    </visual>
    <!-- Collision: simple box for stable physics -->
    <collision>
      <origin xyz="0 0 0.047"/>
      <geometry>
        <box size="0.27 0.1205 0.01"/>
      </geometry>
    </collision>
  </link>
  <!-- base → chassis -->
  <joint name="base_to_chassis" type="fixed">
    <parent link="base_link"/>
    <child link="chassis_link"/>
    <origin rpy="0 0 0" xyz="0 0 0.036"/>
  </joint>
  <!-- ===================== -->
  <!-- Wheel placement       -->
  <!-- ===================== -->
  <!-- Wheel -->
  <link name="rear_left_wheel_link">
    <inertial>
      <mass value="0.0677"/>
      <inertia ixx="3.21561728e-05" ixy="1.40375656e-15" ixz="-3.63476706e-15" iyy="5.65938896e-05" iyz="-1.35718707e-16" izz="3.21561633e-05"/>
    </inertial>
    <visual>
      <origin rpy=" 0 0 3.1412"/>
      <geometry>
        <mesh filename="/home/mohana/robot_ws/src/ackermann_robot/meshes/rear_left_wheel.stl" scale="0.001 0.001 0.001"/>
      </geometry>
      <material name="wheel_black"/>
    </visual>
    <collision>
      <origin rpy="1.5708 0 0"/>
      <geometry>
        <cylinder length="0.03" radius="0.036"/>
      </geometry>
    </collision>
  </link>
  <!-- Gazebo friction for wheels -->
  <!-- <gazebo reference="${name}_wheel_link">
      <mu1>0.8</mu1>
      <mu2>0.8</mu2>
    </gazebo> -->
  <joint name="rear_left_wheel_joint" type="continuous">
    <parent link="chassis_link"/>
    <child link="rear_left_wheel_link"/>
    <origin xyz="-0.1025 0.076 0.036"/>
    <axis xyz="0 1 0"/>
    <!-- <limit lower="-1.5708" upper="1.5708 " effort="1" velocity="10"/> -->
  </joint>
  <!-- Wheel -->
  <link name="rear_right_wheel_link">
    <inertial>
      <mass value="0.0677"/>
      <inertia ixx="3.21561728e-05" ixy="1.40375656e-15" ixz="-3.63476706e-15" iyy="5.65938896e-05" iyz="-1.35718707e-16" izz="3.21561633e-05"/>
    </inertial>
    <visual>
      <origin rpy=" 0 0 3.1412"/>
      <geometry>
        <mesh filename="/home/mohana/robot_ws/src/ackermann_robot/meshes/rear_right_wheel.stl" scale="0.001 0.001 0.001"/>
      </geometry>
      <material name="wheel_black"/>
    </visual>
    <collision>
      <origin rpy="1.5708 0 0"/>
      <geometry>
        <cylinder length="0.03" radius="0.036"/>
      </geometry>
    </collision>
  </link>
  <!-- Gazebo friction for wheels -->
  <!-- <gazebo reference="${name}_wheel_link">
      <mu1>0.8</mu1>
      <mu2>0.8</mu2>
    </gazebo> -->
  <joint name="rear_right_wheel_joint" type="continuous">
    <parent link="chassis_link"/>
    <child link="rear_right_wheel_link"/>
    <origin xyz="-0.1025 -0.076 0.036"/>
    <axis xyz="0 1 0"/>
    <!-- <limit lower="-1.5708" upper="1.5708 " effort="1" velocity="10"/> -->
  </joint>
  <!-- steering knuckle -->
  <link name="front_left_steer_link">
    <inertial>
      <origin xyz="0 0 0"/>
      <mass value="0.01"/>
      <inertia ixx="1e-5" ixy="0" ixz="0" iyy="1e-5" iyz="0" izz="1e-5"/>
    </inertial>
  </link>
  <joint name="front_left_steer_joint" type="revolute">
    <parent link="chassis_link"/>
    <child link="front_left_steer_link"/>
    <origin xyz="0.1025 0.076 0.036"/>
    <axis xyz="0 0 1"/>
    <!-- <limit lower="-0.6" upper="0.6" effort="1" velocity="2"/> -->
  </joint>
  <!-- wheel -->
  <link name="front_left_wheel_link">
    <inertial>
      <mass value="0.0677"/>
      <inertia ixx="3e-5" ixy="0" ixz="0" iyy="3e-5" iyz="0" izz="3e-5"/>
    </inertial>
    <visual>
      <origin rpy="0 0 3.1412"/>
      <geometry>
        <!-- <cylinder radius="${wheel_radius}" length="${wheel_width}"/> -->
        <mesh filename="/home/mohana/robot_ws/src/ackermann_robot/meshes/front_left_wheel.stl" scale="0.001 0.001 0.001"/>
      </geometry>
      <material name="wheel_black"/>
    </visual>
    <collision>
      <origin rpy="1.5708 0 0"/>
      <geometry>
        <cylinder length="0.03" radius="0.036"/>
      </geometry>
    </collision>
  </link>
  <!-- Gazebo friction for wheels -->
  <!-- <gazebo reference="${name}_wheel_link">
      <mu1>1.0</mu1>
      <mu2>0.8</mu2>
    </gazebo> -->
  <joint name="front_left_wheel_joint" type="continuous">
    <parent link="front_left_steer_link"/>
    <child link="front_left_wheel_link"/>
    <axis xyz="0 1 0"/>
    <!-- <limit effort="1" velocity="10"/> -->
    <!-- <limit lower="-1.5708" upper="1.5708" effort="1" velocity="10"/> -->
  </joint>
  <!-- steering knuckle -->
  <link name="front_right_steer_link">
    <inertial>
      <origin xyz="0 0 0"/>
      <mass value="0.01"/>
      <inertia ixx="1e-5" ixy="0" ixz="0" iyy="1e-5" iyz="0" izz="1e-5"/>
    </inertial>
  </link>
  <joint name="front_right_steer_joint" type="revolute">
    <parent link="chassis_link"/>
    <child link="front_right_steer_link"/>
    <origin xyz="0.1025 -0.076 0.036"/>
    <axis xyz="0 0 1"/>
    <!-- <limit lower="-0.6" upper="0.6" effort="1" velocity="2"/> -->
  </joint>
  <!-- wheel -->
  <link name="front_right_wheel_link">
    <inertial>
      <mass value="0.0677"/>
      <inertia ixx="3e-5" ixy="0" ixz="0" iyy="3e-5" iyz="0" izz="3e-5"/>
    </inertial>
    <visual>
      <origin rpy="0 0 3.1412"/>
      <geometry>
        <!-- <cylinder radius="${wheel_radius}" length="${wheel_width}"/> -->
        <mesh filename="/home/mohana/robot_ws/src/ackermann_robot/meshes/front_right_wheel.stl" scale="0.001 0.001 0.001"/>
      </geometry>
      <material name="wheel_black"/>
    </visual>
    <collision>
      <origin rpy="1.5708 0 0"/>
      <geometry>
        <cylinder length="0.03" radius="0.036"/>
      </geometry>
    </collision>
  </link>
  <!-- Gazebo friction for wheels -->
  <!-- <gazebo reference="${name}_wheel_link">
      <mu1>1.0</mu1>
      <mu2>0.8</mu2>
    </gazebo> -->
  <joint name="front_right_wheel_joint" type="continuous">
    <parent link="front_right_steer_link"/>
    <child link="front_right_wheel_link"/>
    <axis xyz="0 1 0"/>
    <!-- <limit effort="1" velocity="10"/> -->
    <!-- <limit lower="-1.5708" upper="1.5708" effort="1" velocity="10"/> -->
  </joint>
  <!-- ===================== -->
  <!-- Gazebo plugins        -->
  <!-- ===================== -->
  <!-- Physics properties for chassis -->
  <!-- <gazebo reference="chassis_link">
    <mu1>0.8</mu1>
    <mu2>0.8</mu2>
  </gazebo>
  
  <gazebo>
    <plugin
      filename="gz-sim-ackermann-steering-system"
      name="gz::sim::systems::AckermannSteering">
      
      <left_steering_joint>front_left_steer_joint</left_steering_joint>
      <right_steering_joint>front_right_steer_joint</right_steering_joint>
      
      <left_joint>front_left_wheel_joint</left_joint>
      <left_joint>rear_left_wheel_joint</left_joint>
      <right_joint>front_right_wheel_joint</right_joint>
      <right_joint>rear_right_wheel_joint</right_joint>

      <wheel_base>${wheelbase}</wheel_base>
      <wheel_separation>${track}</wheel_separation>
      <kingpin_width>${track}</kingpin_width>
      <wheel_radius>${wheel_radius}</wheel_radius>

      <steering_limit>0.5</steering_limit> -->
  <!-- <topic>/cmd_vel</topic>
      <odom_topic>/odometry</odom_topic>
      <tf_topic>/tf</tf_topic>
      <odom_publish_frequency>30</odom_publish_frequency>
    </plugin>
  </gazebo> -->
  <!-- <gazebo>
    <plugin
      filename="gz-sim-joint-state-publisher-system"
      name="gz::sim::systems::JointStatePublisher"/>
      <frame_id>base_link</frame_id>
  </gazebo> -->
</robot>
