<?xml version="1.0" ?>
<!-- =================================================================================== -->
<!-- |    This document was autogenerated by xacro from src/ackermann_robot/urdf/ackermann_robot.xacro | -->
<!-- |    EDITING THIS FILE BY HAND IS NOT RECOMMENDED                                 | -->
<!-- =================================================================================== -->
<robot name="ackermann_robot">
  <!-- ===================== -->
  <!-- Real hardware values  -->
  <!-- ===================== -->
  <!-- Materials -->
  <material name="chassis_black">
    <color rgba="1.0 0.0 0.0 1"/>
  </material>
  <material name="wheel_black">
    <color rgba="0.05 0.05 0.05 1"/>
  </material>
  <!-- ===================== -->
  <!-- Base frame            -->
  <!-- ===================== -->
  <!-- Robot center reference -->
  <link name="base_link"/>
  <!-- ===================== -->
  <!-- Chassis               -->
  <!-- ===================== -->
  <link name="chassis_link">
    <inertial>
      <origin xyz="0 0 0"/>
      <mass value="0.126"/>
      <inertia ixx="0.002" ixy="0" ixz="0" iyy="0.002" iyz="0" izz="0.002"/>
    </inertial>
    <!-- Bottom plate -->
    <visual>
      <origin rpy="0 0 1.5708" xyz="-0.0027 -0.001205 0.0385"/>
      <geometry>
        <mesh filename="/home/mohana/robot_ws/install/ackermann_robot/share/ackermann_robot/meshes/chassis_visual.stl" scale="0.001 0.001 0.001"/>
      </geometry>
      <material name="chassis_black"/>
    </visual>
    <!-- Top plate -->
    <visual>
      <origin rpy="0 0 1.5708" xyz="-0.0027 -0.001205 0.0805"/>
      <geometry>
        <mesh filename="/home/mohana/robot_ws/install/ackermann_robot/share/ackermann_robot/meshes/chassis_visual.stl" scale="0.001 0.001 0.001"/>
      </geometry>
      <material name="chassis_black"/>
    </visual>
    <!-- Front left standoff -->
    <visual>
      <origin rpy="0 0 0" xyz="0.115 0.040249999999999994 0.0595"/>
      <geometry>
        <cylinder length="0.04" radius="0.004"/>
      </geometry>
      <material name="wheel_black"/>
    </visual>
    <!-- Front right -->
    <visual>
      <origin rpy="0 0 0" xyz="0.115 -0.040249999999999994 0.0595"/>
      <geometry>
        <cylinder length="0.04" radius="0.004"/>
      </geometry>
      <material name="wheel_black"/>
    </visual>
    <!-- Rear left -->
    <visual>
      <origin rpy="0 0 0" xyz="-0.115 0.040249999999999994 0.0595"/>
      <geometry>
        <cylinder length="0.04" radius="0.004"/>
      </geometry>
      <material name="wheel_black"/>
    </visual>
    <!-- Rear right -->
    <visual>
      <origin rpy="0 0 0" xyz="-0.115 -0.040249999999999994 0.0595"/>
      <geometry>
        <cylinder length="0.04" radius="0.004"/>
      </geometry>
      <material name="wheel_black"/>
    </visual>
    <!-- Collision: simple box for stable physics -->
    <collision>
      <origin xyz="0 0 0.001"/>
      <geometry>
        <box size="0.27 0.1205 0.002"/>
      </geometry>
    </collision>
  </link>
  <!-- base → chassis -->
  <joint name="base_to_chassis" type="fixed">
    <parent link="base_link"/>
    <child link="chassis_link"/>
    <origin rpy="0 0 0" xyz="0 0 0.0375"/>
  </joint>
  <!-- ===================== -->
  <!-- Wheel placement       -->
  <!-- ===================== -->
  <!-- Wheel -->
  <link name="rear_left_wheel_link">
    <inertial>
      <mass value="0.05"/>
      <inertia ixx="3e-5" ixy="0" ixz="0" iyy="3e-5" iyz="0" izz="3e-5"/>
    </inertial>
    <visual>
      <origin rpy="1.5708 0 0"/>
      <geometry>
        <mesh filename="/home/mohana/robot_ws/install/ackermann_robot/share/ackermann_robot/meshes/wheel_visual.stl" scale="0.001 0.001 0.001"/>
      </geometry>
      <material name="wheel_black"/>
    </visual>
    <collision>
      <origin rpy="1.5708 0 0"/>
      <geometry>
        <cylinder length="0.03" radius="0.0375"/>
      </geometry>
      <surface>
        <friction>
          <ode>
            <mu>0.5</mu>
            <mu2>1.0</mu2>
            <fdir1>0 0 1</fdir1>
          </ode>
          <bullet>
            <friction>0.5</friction>
            <friction2>1</friction2>
            <rolling_friction>0.1</rolling_friction>
          </bullet>
        </friction>
      </surface>
    </collision>
  </link>
  <!-- Gazebo friction for wheels -->
  <gazebo reference="rear_left_wheel_link">
    <mu1>0.8</mu1>
    <mu2>0.8</mu2>
    <kp>1000000.0</kp>
    <kd>100.0</kd>
  </gazebo>
  <joint name="rear_left_wheel_joint" type="revolute">
    <parent link="chassis_link"/>
    <child link="rear_left_wheel_link"/>
    <origin xyz="-0.095 0.076 0.0375"/>
    <axis xyz="0 1 0"/>
    <limit effort="10" velocity="10"/>
  </joint>
  <!-- Wheel -->
  <link name="rear_right_wheel_link">
    <inertial>
      <mass value="0.05"/>
      <inertia ixx="3e-5" ixy="0" ixz="0" iyy="3e-5" iyz="0" izz="3e-5"/>
    </inertial>
    <visual>
      <origin rpy="1.5708 0 0"/>
      <geometry>
        <mesh filename="/home/mohana/robot_ws/install/ackermann_robot/share/ackermann_robot/meshes/wheel_visual.stl" scale="0.001 0.001 0.001"/>
      </geometry>
      <material name="wheel_black"/>
    </visual>
    <collision>
      <origin rpy="1.5708 0 0"/>
      <geometry>
        <cylinder length="0.03" radius="0.0375"/>
      </geometry>
      <surface>
        <friction>
          <ode>
            <mu>0.5</mu>
            <mu2>1.0</mu2>
            <fdir1>0 0 1</fdir1>
          </ode>
          <bullet>
            <friction>0.5</friction>
            <friction2>1</friction2>
            <rolling_friction>0.1</rolling_friction>
          </bullet>
        </friction>
      </surface>
    </collision>
  </link>
  <!-- Gazebo friction for wheels -->
  <gazebo reference="rear_right_wheel_link">
    <mu1>0.8</mu1>
    <mu2>0.8</mu2>
    <kp>1000000.0</kp>
    <kd>100.0</kd>
  </gazebo>
  <joint name="rear_right_wheel_joint" type="revolute">
    <parent link="chassis_link"/>
    <child link="rear_right_wheel_link"/>
    <origin xyz="-0.095 -0.076 0.0375"/>
    <axis xyz="0 1 0"/>
    <limit effort="10" velocity="10"/>
  </joint>
  <!-- steering knuckle -->
  <link name="front_left_steer_link">
    <inertial>
      <origin xyz="0 0 0"/>
      <mass value="0.01"/>
      <inertia ixx="1e-5" ixy="0" ixz="0" iyy="1e-5" iyz="0" izz="1e-5"/>
    </inertial>
  </link>
  <joint name="front_left_steer_joint" type="revolute">
    <parent link="chassis_link"/>
    <child link="front_left_steer_link"/>
    <origin xyz="0.095 0.076 0.0375"/>
    <axis xyz="0 0 1"/>
    <limit effort="25" lower="-0.6" upper="0.6" velocity="2"/>
  </joint>
  <!-- wheel -->
  <link name="front_left_wheel_link">
    <inertial>
      <mass value="0.05"/>
      <inertia ixx="3e-5" ixy="0" ixz="0" iyy="3e-5" iyz="0" izz="3e-5"/>
    </inertial>
    <visual>
      <origin rpy="1.5708 0 0"/>
      <geometry>
        <!-- <cylinder radius="${wheel_radius}" length="${wheel_width}"/> -->
        <mesh filename="/home/mohana/robot_ws/install/ackermann_robot/share/ackermann_robot/meshes/wheel_visual.stl" scale="0.001 0.001 0.001"/>
      </geometry>
      <material name="wheel_black"/>
    </visual>
    <collision>
      <origin rpy="1.5708 0 0"/>
      <geometry>
        <cylinder length="0.03" radius="0.0375"/>
      </geometry>
      <surface>
        <friction>
          <ode>
            <mu>0.5</mu>
            <mu2>1.0</mu2>
            <fdir1>0 0 1</fdir1>
          </ode>
          <bullet>
            <friction>0.5</friction>
            <friction2>1</friction2>
            <rolling_friction>0.1</rolling_friction>
          </bullet>
        </friction>
      </surface>
    </collision>
  </link>
  <!-- Gazebo friction for wheels -->
  <gazebo reference="front_left_wheel_link">
    <mu1>0.8</mu1>
    <mu2>0.8</mu2>
    <kp>1000000.0</kp>
    <kd>100.0</kd>
  </gazebo>
  <joint name="front_left_wheel_joint" type="revolute">
    <parent link="front_left_steer_link"/>
    <child link="front_left_wheel_link"/>
    <axis xyz="0 1 0"/>
    <limit effort="10" velocity="10"/>
  </joint>
  <!-- steering knuckle -->
  <link name="front_right_steer_link">
    <inertial>
      <origin xyz="0 0 0"/>
      <mass value="0.01"/>
      <inertia ixx="1e-5" ixy="0" ixz="0" iyy="1e-5" iyz="0" izz="1e-5"/>
    </inertial>
  </link>
  <joint name="front_right_steer_joint" type="revolute">
    <parent link="chassis_link"/>
    <child link="front_right_steer_link"/>
    <origin xyz="0.095 -0.076 0.0375"/>
    <axis xyz="0 0 1"/>
    <limit effort="25" lower="-0.6" upper="0.6" velocity="2"/>
  </joint>
  <!-- wheel -->
  <link name="front_right_wheel_link">
    <inertial>
      <mass value="0.05"/>
      <inertia ixx="3e-5" ixy="0" ixz="0" iyy="3e-5" iyz="0" izz="3e-5"/>
    </inertial>
    <visual>
      <origin rpy="1.5708 0 0"/>
      <geometry>
        <!-- <cylinder radius="${wheel_radius}" length="${wheel_width}"/> -->
        <mesh filename="/home/mohana/robot_ws/install/ackermann_robot/share/ackermann_robot/meshes/wheel_visual.stl" scale="0.001 0.001 0.001"/>
      </geometry>
      <material name="wheel_black"/>
    </visual>
    <collision>
      <origin rpy="1.5708 0 0"/>
      <geometry>
        <cylinder length="0.03" radius="0.0375"/>
      </geometry>
      <surface>
        <friction>
          <ode>
            <mu>0.5</mu>
            <mu2>1.0</mu2>
            <fdir1>0 0 1</fdir1>
          </ode>
          <bullet>
            <friction>0.5</friction>
            <friction2>1</friction2>
            <rolling_friction>0.1</rolling_friction>
          </bullet>
        </friction>
      </surface>
    </collision>
  </link>
  <!-- Gazebo friction for wheels -->
  <gazebo reference="front_right_wheel_link">
    <mu1>0.8</mu1>
    <mu2>0.8</mu2>
    <kp>1000000.0</kp>
    <kd>100.0</kd>
  </gazebo>
  <joint name="front_right_wheel_joint" type="revolute">
    <parent link="front_right_steer_link"/>
    <child link="front_right_wheel_link"/>
    <axis xyz="0 1 0"/>
    <limit effort="10" velocity="10"/>
  </joint>
  <!-- ===================== -->
  <!-- Gazebo plugins        -->
  <!-- ===================== -->
  <!-- Physics properties for chassis -->
  <gazebo reference="chassis_link">
    <mu1>0.2</mu1>
    <mu2>0.2</mu2>
    <kp>1000000.0</kp>
    <kd>100.0</kd>
  </gazebo>
  <gazebo>
    <plugin filename="gz-sim-ackermann-steering-system" name="gz::sim::systems::AckermannSteering">
      <left_steering_joint>chassis_link::front_left_steer_joint</left_steering_joint>
      <right_steering_joint>chassis_link::front_right_steer_joint</right_steering_joint>
      <left_joint>front_left_wheel_joint</left_joint>
      <left_joint>rear_left_wheel_joint</left_joint>
      <right_joint>front_right_wheel_joint</right_joint>
      <right_joint>rear_right_wheel_joint</right_joint>
      <wheel_base>0.19</wheel_base>
      <wheel_separation>0.152</wheel_separation>
      <kingpin_width>0.152</kingpin_width>
      <wheel_radius>0.0375</wheel_radius>
      <steering_limit>0.5</steering_limit>
      <max_velocity>1.0</max_velocity>
      <max_acceleration>2.0</max_acceleration>
      <topic>/cmd_vel</topic>
      <odom_topic>/odometry</odom_topic>
      <tf_topic>/tf</tf_topic>
      <frame_id>odom</frame_id>
      <child_frame_id>base_link</child_frame_id>
      <odom_publish_frequency>30</odom_publish_frequency>
    </plugin>
  </gazebo>
  <gazebo>
    <plugin filename="gz-sim-joint-state-publisher-system" name="gz::sim::systems::JointStatePublisher"/>
    <!-- <topic>joint_states</topic> -->
  </gazebo>
</robot>
