<?xml version="1.0" ?>
<sdf version="1.7">
  <model name="ackermann_robot">
    <link name="base_link"/>
    <link name="chassis_link">
      <inertial>
        <pose>0 0 0.0385 0 0 0</pose>
        <mass>0.126</mass>
        <inertia>
          <ixx>0.002</ixx>
          <ixy>0</ixy>
          <ixz>0</ixz>
          <iyy>0.002</iyy>
          <iyz>0</iyz>
          <izz>0.002</izz>
        </inertia>
      </inertial>
      <visual name="chassis_visual">
        <pose>-0.135 -0.06025 0.0385 0 0 0</pose>
        <geometry>
          <mesh>
            <uri>/home/mohana/robot_ws/install/ackermann_robot/share/ackermann_robot/meshes/chassis_visual.dae</uri>
            <scale>1 1 1</scale>
          </mesh>
        </geometry>
        <material>
          <ambient>1.0 0.0 0.0 1</ambient>
          <diffuse>1.0 0.0 0.0 1</diffuse>
        </material>
      </visual>
      <collision name="chassis_collision">
        <pose>0 0 0.0385 0 0 0</pose>
        <geometry>
          <box>
            <size>0.27 0.1205 0.002</size>
          </box>
        </geometry>
      </collision>
    </link>
    <joint name="base_to_chassis" type="fixed">
      <parent>base_link</parent>
      <child>chassis_link</child>
    </joint>
    <link name="rear_left_wheel_link">
      <inertial>
        <mass>0.05</mass>
        <inertia>
          <pose>0 0 0</pose>
          <ixx>3e-5</ixx>
          <ixy>0</ixy>
          <ixz>0</ixz>
          <iyy>3e-5</iyy>
          <iyz>0</iyz>
          <izz>3e-5</izz>
        </inertia>
      </inertial>
      <visual name="rear_left_wheel_visual">
        <pose>0 0 0 1.5708 0 0</pose>
        <geometry>
          <cylinder>
            <length>0.03</length>
            <radius>0.0375</radius>
          </cylinder>
        </geometry>
        <material>
          <ambient>0.05 0.05 0.05 1</ambient>
          <diffuse>0.05 0.05 0.05 1</diffuse>
        </material>
      </visual>
      <collision name="rear_left_wheel_collision">
        <pose>0 0 0 1.5708 0 0</pose>
        <geometry>
          <cylinder>
            <length>0.03</length>
            <radius>0.0375</radius>
          </cylinder>
        </geometry>
      </collision>
    </link>
    <joint name="rear_left_wheel_joint" type="revolute">
      <parent>chassis_link</parent>
      <child>rear_left_wheel_link</child>
      <pose>-0.095 0.0835 0.0375 0 0 0</pose>
      <axis>
        <xyz>0 1 0</xyz>
      </axis>
    </joint>
    <link name="rear_right_wheel_link">
      <inertial>
        <mass>0.05</mass>
        <inertia>
          <ixx>3e-5</ixx>
          <ixy>0</ixy>
          <ixz>0</ixz>
          <iyy>3e-5</iyy>
          <iyz>0</iyz>
          <izz>3e-5</izz>
        </inertia>
      </inertial>
      <visual name="rear_right_wheel_visual">
        <pose>0 0 0 1.5708 0 0</pose>
        <geometry>
          <cylinder>
            <length>0.03</length>
            <radius>0.0375</radius>
          </cylinder>
        </geometry>
        <material>
          <ambient>0.05 0.05 0.05 1</ambient>
          <diffuse>0.05 0.05 0.05 1</diffuse>
        </material>
      </visual>
      <collision name="rear_right_wheel_collision">
        <pose>0 0 0 1.5708 0 0</pose>
        <geometry>
          <cylinder>
            <length>0.03</length>
            <radius>0.0375</radius>
          </cylinder>
        </geometry>
      </collision>
    </link>
    <joint name="rear_right_wheel_joint" type="revolute">
      <parent>chassis_link</parent>
      <child>rear_right_wheel_link</child>
      <pose>-0.095 -0.0835 0.0375 0 0 0</pose>
      <axis>
        <xyz>0 1 0</xyz>
      </axis>
    </joint>
    <link name="front_left_steer_link">
      <inertial>
        <mass>0.01</mass>
        <inertia>
          <ixx>1e-5</ixx>
          <ixy>0</ixy>
          <ixz>0</ixz>
          <iyy>1e-5</iyy>
          <iyz>0</iyz>
          <izz>1e-5</izz>
        </inertia>
      </inertial>
    </link>
    <joint name="front_left_steer_joint" type="revolute">
      <parent>chassis_link</parent>
      <child>front_left_steer_link</child>
      <pose>0.095 0.0835 0.0375 0 0 0</pose>
      <axis>
        <xyz>0 0 1</xyz>
        <limit>
          <lower>-0.6</lower>
          <upper>0.6</upper>
          <effort>10</effort>
          <velocity>2</velocity>
        </limit>
      </axis>
    </joint>
    <link name="front_left_wheel_link">
      <inertial>
        <mass>0.05</mass>
        <inertia>
          <ixx>3e-5</ixx>
          <ixy>0</ixy>
          <ixz>0</ixz>
          <iyy>3e-5</iyy>
          <iyz>0</iyz>
          <izz>3e-5</izz>
        </inertia>
      </inertial>
      <visual name="front_left_wheel_visual">
        <pose>0 0 0 1.5708 0 0</pose>
        <geometry>
          <cylinder>
            <length>0.03</length>
            <radius>0.0375</radius>
          </cylinder>
        </geometry>
        <material>
          <ambient>0.05 0.05 0.05 1</ambient>
          <diffuse>0.05 0.05 0.05 1</diffuse>
        </material>
      </visual>
      <collision name="front_left_wheel_collision">
        <pose>0 0 0 1.5708 0 0</pose>
        <geometry>
          <cylinder>
            <length>0.03</length>
            <radius>0.0375</radius>
          </cylinder>
        </geometry>
      </collision>
    </link>
    <joint name="front_left_wheel_joint" type="revolute">
      <parent>front_left_steer_link</parent>
      <child>front_left_wheel_link</child>
      <axis>
        <xyz>0 1 0</xyz>
      </axis>
    </joint>
    <link name="front_right_steer_link">
      <inertial>
        <mass>0.01</mass>
        <inertia>
          <ixx>1e-5</ixx>
          <ixy>0</ixy>
          <ixz>0</ixz>
          <iyy>1e-5</iyy>
          <iyz>0</iyz>
          <izz>1e-5</izz>
        </inertia>
      </inertial>
    </link>
    <joint name="front_right_steer_joint" type="revolute">
      <parent>chassis_link</parent>
      <child>front_right_steer_link</child>
      <pose>0.095 -0.0835 0.0375 0 0 0</pose>
      <axis>
        <xyz>0 0 1</xyz>
        <limit>
          <lower>-0.6</lower>
          <upper>0.6</upper>
          <effort>10</effort>
          <velocity>2</velocity>
        </limit>
      </axis>
    </joint>
    <link name="front_right_wheel_link">
      <inertial>
        <mass>0.05</mass>
        <inertia>
          <ixx>3e-5</ixx>
          <ixy>0</ixy>
          <ixz>0</ixz>
          <iyy>3e-5</iyy>
          <iyz>0</iyz>
          <izz>3e-5</izz>
        </inertia>
      </inertial>
      <visual name="front_right_wheel_visual">
        <pose>0 0 0 1.5708 0 0</pose>
        <geometry>
          <cylinder>
            <length>0.03</length>
            <radius>0.0375</radius>
          </cylinder>
        </geometry>
        <material>
          <ambient>0.05 0.05 0.05 1</ambient>
          <diffuse>0.05 0.05 0.05 1</diffuse>
        </material>
      </visual>
      <collision name="front_right_wheel_collision">
        <pose>0 0 0 1.5708 0 0</pose>
        <geometry>
          <cylinder>
            <length>0.03</length>
            <radius>0.0375</radius>
          </cylinder>
        </geometry>
      </collision>
    </link>
    <joint name="front_right_wheel_joint" type="revolute">
      <parent>front_right_steer_link</parent>
      <child>front_right_wheel_link</child>
      <axis>
        <xyz>0 1 0</xyz>
      </axis>
    </joint>
  </model>
</sdf>