<?xml version="1.0" ?>
<!-- =================================================================================== -->
<!-- |    This document was autogenerated by xacro from src/ackermann_robot/urdf/ackermann_robot.xacro | -->
<!-- |    EDITING THIS FILE BY HAND IS NOT RECOMMENDED                                 | -->
<!-- =================================================================================== -->
<robot name="ackermann_robot">
  <link name="imu_link">
    <inertial>
      <mass value="0.001"/>
      <inertia ixx="1e-6" ixy="0" ixz="0" iyy="1e-6" iyz="0" izz="1e-6"/>
    </inertial>
  </link>
  <joint name="imu_joint" type="fixed">
    <parent link="base_link"/>
    <child link="imu_link"/>
    <origin rpy="0 0 0" xyz="0 0 0.05"/>
  </joint>
  <gazebo reference="imu_joint">
    <preserveFixedJoint>true</preserveFixedJoint>
  </gazebo>
  <gazebo reference="imu_link">
    <sensor name="imu_sensor" type="imu">
      <always_on>1</always_on>
      <update_rate>1000</update_rate>
      <topic>/imu</topic>
    </sensor>
  </gazebo>
  <link name="front_camera_link">
    <visual>
      <origin rpy="0 0 0" xyz="0 0 0"/>
      <geometry>
        <box size="0.02 0.02 0.02"/>
      </geometry>
      <material name="wheel_black"/>
    </visual>
  </link>
  <joint name="front_camera_joint" type="fixed">
    <parent link="base_link"/>
    <child link="front_camera_link"/>
    <origin rpy="0.0 0.0 0.0" xyz="0.135 0.0 0.08"/>
  </joint>
  <gazebo reference="front_camera_link">
    <sensor name="front_camera" type="camera">
      <camera>
        <horizontal_fov>3.14159</horizontal_fov>
        <image>
          <width>800</width>
          <height>800</height>
          <format>R8G8B8</format>
        </image>
        <clip>
          <near>0.1</near>
          <far>100</far>
        </clip>
        <lens>
          <type>fisheye</type>
          <scale_to_hfov>true</scale_to_hfov>
          <mapping>equidistant</mapping>
        </lens>
      </camera>
      <always_on>1</always_on>
      <update_rate>30</update_rate>
      <visualize>true</visualize>
      <topic>front_camera/image</topic>
    </sensor>
  </gazebo>
  <!-- fx="774.65" fy="776.83" cx="400" cy="400"
    k1="-0.01948" k2="-0.00302" k3="-0.00063" p1="0.00009" /> -->
  <link name="left_camera_link">
    <visual>
      <origin rpy="0 0 0" xyz="0 0 0"/>
      <geometry>
        <box size="0.02 0.02 0.02"/>
      </geometry>
      <material name="wheel_black"/>
    </visual>
  </link>
  <joint name="left_camera_joint" type="fixed">
    <parent link="base_link"/>
    <child link="left_camera_link"/>
    <origin rpy="0.0 0.0 1.5708" xyz="0.0 0.06025 0.08"/>
  </joint>
  <gazebo reference="left_camera_link">
    <sensor name="left_camera" type="camera">
      <camera>
        <horizontal_fov>3.14159</horizontal_fov>
        <image>
          <width>800</width>
          <height>800</height>
          <format>R8G8B8</format>
        </image>
        <clip>
          <near>0.1</near>
          <far>100</far>
        </clip>
        <lens>
          <type>fisheye</type>
          <scale_to_hfov>true</scale_to_hfov>
          <mapping>equidistant</mapping>
        </lens>
      </camera>
      <always_on>1</always_on>
      <update_rate>30</update_rate>
      <visualize>true</visualize>
      <topic>left_camera/image</topic>
    </sensor>
  </gazebo>
  <!-- fx="413.44" fy="414.56" cx="625.46" cy="393.99"
    k1="0.2422" k2="0.5059" k3="-0.4873" p1="0.1775" /> -->
  <link name="right_camera_link">
    <visual>
      <origin rpy="0 0 0" xyz="0 0 0"/>
      <geometry>
        <box size="0.02 0.02 0.02"/>
      </geometry>
      <material name="wheel_black"/>
    </visual>
  </link>
  <joint name="right_camera_joint" type="fixed">
    <parent link="base_link"/>
    <child link="right_camera_link"/>
    <origin rpy="0.0 0.0 -1.5708" xyz="0.0 -0.06025 0.08"/>
  </joint>
  <gazebo reference="right_camera_link">
    <sensor name="right_camera" type="camera">
      <camera>
        <horizontal_fov>3.14159</horizontal_fov>
        <image>
          <width>800</width>
          <height>800</height>
          <format>R8G8B8</format>
        </image>
        <clip>
          <near>0.1</near>
          <far>100</far>
        </clip>
        <lens>
          <type>fisheye</type>
          <scale_to_hfov>true</scale_to_hfov>
          <mapping>equidistant</mapping>
        </lens>
      </camera>
      <always_on>1</always_on>
      <update_rate>30</update_rate>
      <visualize>true</visualize>
      <topic>right_camera/image</topic>
    </sensor>
  </gazebo>
  <!-- fx="405.08" fy="405.38" cx="642.53" cy="392.78"
    k1="0.2355" k2="0.5192" k3="-0.5069" p1="0.1963" /> -->
  <link name="rear_camera_link">
    <visual>
      <origin rpy="0 0 0" xyz="0 0 0"/>
      <geometry>
        <box size="0.02 0.02 0.02"/>
      </geometry>
      <material name="wheel_black"/>
    </visual>
  </link>
  <joint name="rear_camera_joint" type="fixed">
    <parent link="base_link"/>
    <child link="rear_camera_link"/>
    <origin rpy="0.0 0.0 3.14159" xyz="-0.135 0.0 0.08"/>
  </joint>
  <gazebo reference="rear_camera_link">
    <sensor name="rear_camera" type="camera">
      <camera>
        <horizontal_fov>3.14159</horizontal_fov>
        <image>
          <width>800</width>
          <height>800</height>
          <format>R8G8B8</format>
        </image>
        <clip>
          <near>0.1</near>
          <far>100</far>
        </clip>
        <lens>
          <type>fisheye</type>
          <scale_to_hfov>true</scale_to_hfov>
          <mapping>equidistant</mapping>
        </lens>
      </camera>
      <always_on>1</always_on>
      <update_rate>30</update_rate>
      <visualize>true</visualize>
      <topic>rear_camera/image</topic>
    </sensor>
  </gazebo>
  <!-- fx="399.45" fy="399.77" cx="623.44" cy="387.16"
    k1="0.2565" k2="0.4095" k3="-0.3257" p1="0.1022" /> -->
  <!-- <xacro:sensor_camera name="front_camera" parent="base_link">
    <origin xyz="0.135 0 0.072" rpy="0 0.0 0"/>
  </xacro:sensor_camera>

  <xacro:sensor_camera name="rear_camera" parent="base_link">
    <origin xyz="-0.135 0 0.072" rpy="0 0.0 ${pi}"/>
  </xacro:sensor_camera>

  <xacro:sensor_camera name="left_camera" parent="base_link">
    <origin xyz="0.0 0.06025 0.072" rpy="0 0.0 ${pi/2}"/>
  </xacro:sensor_camera>

  <xacro:sensor_camera name="right_camera" parent="base_link">
    <origin xyz="0.0 -0.06025 0.072" rpy="0 0.0 ${-pi/2}"/>
  </xacro:sensor_camera> -->
  <!-- ===================== -->
  <!-- Real hardware values  -->
  <!-- ===================== -->
  <!-- <xacro:property name="pi" value="3.1415926535897932384626"/> -->
  <!-- Materials -->
  <material name="chassis_red">
    <color rgba="1.0 0.0 0.0 1"/>
  </material>
  <material name="wheel_black">
    <color rgba="0.05 0.05 0.05 1"/>
  </material>
  <!-- ===================== -->
  <!-- Base frame            -->
  <!-- ===================== -->
  <!-- Robot center reference -->
  <link name="base_link"/>
  <!-- ===================== -->
  <!-- Chassis               -->
  <!-- ===================== -->
  <link name="chassis_link">
    <inertial>
      <origin xyz="0 0 0.022"/>
      <mass value="0.13442"/>
      <inertia ixx="1.50903123e-04" ixy="4.70052075e-08" ixz="6.59784866e-15" iyy="8.14177826e-04" iyz="1.01460270e-15" izz="9.64991335e-04"/>
    </inertial>
    <!-- Bottom plate -->
    <visual>
      <origin rpy="0 0 0" xyz="0 0 0.037"/>
      <geometry>
        <mesh filename="package://ackermann_robot/meshes/chassis_visual.stl" scale="0.001 0.001 0.001"/>
      </geometry>
      <material name="chassis_red"/>
    </visual>
    <!-- Top plate -->
    <visual>
      <origin rpy="0 0 0" xyz="0 0 0.079"/>
      <geometry>
        <mesh filename="package://ackermann_robot/meshes/chassis_visual.stl" scale="0.001 0.001 0.001"/>
      </geometry>
      <material name="chassis_red"/>
    </visual>
    <!-- Front left standoff -->
    <visual>
      <origin rpy="0 0 0" xyz="0.115 0.040249999999999994 0.057999999999999996"/>
      <geometry>
        <cylinder length="0.04" radius="0.004"/>
      </geometry>
      <material name="wheel_black"/>
    </visual>
    <!-- Front right -->
    <visual>
      <origin rpy="0 0 0" xyz="0.115 -0.040249999999999994 0.057999999999999996"/>
      <geometry>
        <cylinder length="0.04" radius="0.004"/>
      </geometry>
      <material name="wheel_black"/>
    </visual>
    <!-- Rear left -->
    <visual>
      <origin rpy="0 0 0" xyz="-0.115 0.040249999999999994 0.057999999999999996"/>
      <geometry>
        <cylinder length="0.04" radius="0.004"/>
      </geometry>
      <material name="wheel_black"/>
    </visual>
    <!-- Rear right -->
    <visual>
      <origin rpy="0 0 0" xyz="-0.115 -0.040249999999999994 0.057999999999999996"/>
      <geometry>
        <cylinder length="0.04" radius="0.004"/>
      </geometry>
      <material name="wheel_black"/>
    </visual>
    <!-- Collision: simple box for stable physics -->
    <collision>
      <origin xyz="0 0 0.057999999999999996"/>
      <geometry>
        <box size="0.27 0.1205 0.044"/>
      </geometry>
    </collision>
  </link>
  <!-- base → chassis -->
  <joint name="base_to_chassis" type="fixed">
    <parent link="base_link"/>
    <child link="chassis_link"/>
    <origin rpy="0 0 0" xyz="0 0 0"/>
  </joint>
  <!-- ===================== -->
  <!-- Wheel placement       -->
  <!-- ===================== -->
  <!-- Wheel -->
  <link name="rear_left_wheel_link">
    <inertial>
      <mass value="0.0677"/>
      <inertia ixx="3.21561728e-05" ixy="1.40375656e-15" ixz="-3.63476706e-15" iyy="5.65938896e-05" iyz="-1.35718707e-16" izz="3.21561633e-05"/>
    </inertial>
    <visual>
      <origin rpy=" 0 0 3.1412"/>
      <geometry>
        <mesh filename="package://ackermann_robot/meshes/rear_left_wheel.stl" scale="0.001 0.001 0.001"/>
      </geometry>
      <material name="wheel_black"/>
    </visual>
    <collision>
      <origin rpy="1.5708 0 0"/>
      <geometry>
        <cylinder length="0.03" radius="0.036"/>
      </geometry>
    </collision>
  </link>
  <!-- Gazebo friction for wheels -->
  <gazebo reference="rear_left_wheel_link">
    <mu1>1.0</mu1>
    <mu2>1.0</mu2>
  </gazebo>
  <joint name="rear_left_wheel_joint" type="continuous">
    <parent link="chassis_link"/>
    <child link="rear_left_wheel_link"/>
    <origin xyz="-0.1025 0.076 0.036"/>
    <axis xyz="0 1 0"/>
  </joint>
  <!-- Wheel -->
  <link name="rear_right_wheel_link">
    <inertial>
      <mass value="0.0677"/>
      <inertia ixx="3.21561728e-05" ixy="1.40375656e-15" ixz="-3.63476706e-15" iyy="5.65938896e-05" iyz="-1.35718707e-16" izz="3.21561633e-05"/>
    </inertial>
    <visual>
      <origin rpy=" 0 0 3.1412"/>
      <geometry>
        <mesh filename="package://ackermann_robot/meshes/rear_right_wheel.stl" scale="0.001 0.001 0.001"/>
      </geometry>
      <material name="wheel_black"/>
    </visual>
    <collision>
      <origin rpy="1.5708 0 0"/>
      <geometry>
        <cylinder length="0.03" radius="0.036"/>
      </geometry>
    </collision>
  </link>
  <!-- Gazebo friction for wheels -->
  <gazebo reference="rear_right_wheel_link">
    <mu1>1.0</mu1>
    <mu2>1.0</mu2>
  </gazebo>
  <joint name="rear_right_wheel_joint" type="continuous">
    <parent link="chassis_link"/>
    <child link="rear_right_wheel_link"/>
    <origin xyz="-0.1025 -0.076 0.036"/>
    <axis xyz="0 1 0"/>
  </joint>
  <!-- steering knuckle -->
  <link name="front_left_steer_link">
    <inertial>
      <origin xyz="0 0 0"/>
      <mass value="0.01"/>
      <inertia ixx="1e-5" ixy="0" ixz="0" iyy="1e-5" iyz="0" izz="1e-5"/>
    </inertial>
  </link>
  <joint name="front_left_steer_joint" type="revolute">
    <parent link="chassis_link"/>
    <child link="front_left_steer_link"/>
    <origin xyz="0.1025 0.076 0.036"/>
    <axis xyz="0 0 1"/>
    <limit effort="10" lower="-0.6" upper="0.6" velocity="2"/>
  </joint>
  <!-- wheel -->
  <link name="front_left_wheel_link">
    <inertial>
      <mass value="0.0677"/>
      <inertia ixx="3e-5" ixy="0" ixz="0" iyy="3e-5" iyz="0" izz="3e-5"/>
    </inertial>
    <visual>
      <origin rpy="0 0 3.1412"/>
      <geometry>
        <!-- <cylinder radius="${wheel_radius}" length="${wheel_width}"/> -->
        <mesh filename="package://ackermann_robot/meshes/front_left_wheel.stl" scale="0.001 0.001 0.001"/>
      </geometry>
      <material name="wheel_black"/>
    </visual>
    <collision>
      <origin rpy="1.5708 0 0"/>
      <geometry>
        <cylinder length="0.03" radius="0.036"/>
      </geometry>
    </collision>
  </link>
  <!-- Gazebo friction for wheels -->
  <gazebo reference="front_left_wheel_link">
    <mu1>1.0</mu1>
    <mu2>1.0</mu2>
  </gazebo>
  <joint name="front_left_wheel_joint" type="continuous">
    <parent link="front_left_steer_link"/>
    <child link="front_left_wheel_link"/>
    <axis xyz="0 1 0"/>
  </joint>
  <!-- steering knuckle -->
  <link name="front_right_steer_link">
    <inertial>
      <origin xyz="0 0 0"/>
      <mass value="0.01"/>
      <inertia ixx="1e-5" ixy="0" ixz="0" iyy="1e-5" iyz="0" izz="1e-5"/>
    </inertial>
  </link>
  <joint name="front_right_steer_joint" type="revolute">
    <parent link="chassis_link"/>
    <child link="front_right_steer_link"/>
    <origin xyz="0.1025 -0.076 0.036"/>
    <axis xyz="0 0 1"/>
    <limit effort="10" lower="-0.6" upper="0.6" velocity="2"/>
  </joint>
  <!-- wheel -->
  <link name="front_right_wheel_link">
    <inertial>
      <mass value="0.0677"/>
      <inertia ixx="3e-5" ixy="0" ixz="0" iyy="3e-5" iyz="0" izz="3e-5"/>
    </inertial>
    <visual>
      <origin rpy="0 0 3.1412"/>
      <geometry>
        <!-- <cylinder radius="${wheel_radius}" length="${wheel_width}"/> -->
        <mesh filename="package://ackermann_robot/meshes/front_right_wheel.stl" scale="0.001 0.001 0.001"/>
      </geometry>
      <material name="wheel_black"/>
    </visual>
    <collision>
      <origin rpy="1.5708 0 0"/>
      <geometry>
        <cylinder length="0.03" radius="0.036"/>
      </geometry>
    </collision>
  </link>
  <!-- Gazebo friction for wheels -->
  <gazebo reference="front_right_wheel_link">
    <mu1>1.0</mu1>
    <mu2>1.0</mu2>
  </gazebo>
  <joint name="front_right_wheel_joint" type="continuous">
    <parent link="front_right_steer_link"/>
    <child link="front_right_wheel_link"/>
    <axis xyz="0 1 0"/>
  </joint>
  <!-- ===================== -->
  <!-- Gazebo plugins        -->
  <!-- ===================== -->
  <!-- Physics properties for chassis -->
  <gazebo reference="chassis_link">
    <mu1>0.8</mu1>
    <mu2>0.8</mu2>
  </gazebo>
  <gazebo>
    <plugin filename="gz-sim-ackermann-steering-system" name="gz::sim::systems::AckermannSteering">
      <left_steering_joint>front_left_steer_joint</left_steering_joint>
      <right_steering_joint>front_right_steer_joint</right_steering_joint>
      <left_joint>rear_left_wheel_joint</left_joint>
      <right_joint>rear_right_wheel_joint</right_joint>
      <wheel_base>0.205</wheel_base>
      <wheel_separation>0.152</wheel_separation>
      <kingpin_width>0.152</kingpin_width>
      <wheel_radius>0.036</wheel_radius>
      <steering_limit>0.5</steering_limit>
      <topic>/cmd_vel</topic>
      <odom_topic>/odometry</odom_topic>
      <frame_id>odom</frame_id>
      <child_frame_id>base_link</child_frame_id>
      <odom_publish_frequency>30</odom_publish_frequency>
    </plugin>
    <plugin filename="gz-sim-pose-publisher-system" name="gz::sim::systems::PosePublisher">
      <publish_link_pose>true</publish_link_pose>
      <publish_sensor_pose>true</publish_sensor_pose>
      <publish_model_pose>true</publish_model_pose>
      <use_pose_vector_msg>true</use_pose_vector_msg>
    </plugin>
    <plugin filename="gz-sim-odometry-publisher-system" name="gz::sim::systems::OdometryPublisher">
      <odom_frame>ground_truth_odom</odom_frame>
      <robot_base_frame>base_link</robot_base_frame>
      <odom_topic>/ground_truth_odom</odom_topic>
      <dimensions>3</dimensions>
    </plugin>
    <plugin filename="gz-sim-joint-state-publisher-system" name="gz::sim::systems::JointStatePublisher"/>
  </gazebo>
</robot>
