<?xml version="1.0" ?>
<!-- =================================================================================== -->
<!-- |    This document was autogenerated by xacro from src/ackermann_robot/urdf/ackermann_robot.xacro | -->
<!-- |    EDITING THIS FILE BY HAND IS NOT RECOMMENDED                                 | -->
<!-- =================================================================================== -->
<robot name="ackermann_robot">
  <!-- ===================== -->
  <!-- Real hardware values  -->
  <!-- ===================== -->
  <!-- Materials -->
  <material name="chassis_black">
    <color rgba="1.0 0.0 0.0 1"/>
  </material>
  <material name="wheel_black">
    <color rgba="0.05 0.05 0.05 1"/>
  </material>
  <!-- ===================== -->
  <!-- Base frame            -->
  <!-- ===================== -->
  <!-- Robot center reference -->
  <link name="base_link"/>
  <!-- ===================== -->
  <!-- Chassis               -->
  <!-- ===================== -->
  <link name="chassis_link">
    <inertial>
      <origin xyz="0 0 0"/>
      <mass value="0.126"/>
      <inertia ixx="0.002" ixy="0" ixz="0" iyy="0.002" iyz="0" izz="0.002"/>
    </inertial>
    <!-- Bottom plate -->
    <visual>
      <origin rpy="0 0 1.5708" xyz="-0.0027 -0.001205 0.0385"/>
      <geometry>
        <mesh filename="package://ackermann_robot/meshes/chassis_visual.stl" scale="0.001 0.001 0.001"/>
      </geometry>
      <material name="chassis_black"/>
    </visual>
    <!-- Top plate -->
    <visual>
      <origin rpy="0 0 1.5708" xyz="-0.0027 -0.001205 0.0805"/>
      <geometry>
        <mesh filename="package://ackermann_robot/meshes/chassis_visual.stl" scale="0.001 0.001 0.001"/>
      </geometry>
      <material name="chassis_black"/>
    </visual>
    <!-- Front left standoff -->
    <visual>
      <origin rpy="0 0 0" xyz="0.115 0.040249999999999994 0.0595"/>
      <geometry>
        <cylinder length="0.04" radius="0.004"/>
      </geometry>
      <material name="wheel_black"/>
    </visual>
    <!-- Front right -->
    <visual>
      <origin rpy="0 0 0" xyz="0.115 -0.040249999999999994 0.0595"/>
      <geometry>
        <cylinder length="0.04" radius="0.004"/>
      </geometry>
      <material name="wheel_black"/>
    </visual>
    <!-- Rear left -->
    <visual>
      <origin rpy="0 0 0" xyz="-0.115 0.040249999999999994 0.0595"/>
      <geometry>
        <cylinder length="0.04" radius="0.004"/>
      </geometry>
      <material name="wheel_black"/>
    </visual>
    <!-- Rear right -->
    <visual>
      <origin rpy="0 0 0" xyz="-0.115 -0.040249999999999994 0.0595"/>
      <geometry>
        <cylinder length="0.04" radius="0.004"/>
      </geometry>
      <material name="wheel_black"/>
    </visual>
    <!-- Collision: simple box for stable physics -->
    <collision>
      <origin xyz="0 0 0.001"/>
      <geometry>
        <box size="0.27 0.1205 0.002"/>
      </geometry>
    </collision>
  </link>
  <!-- base → chassis -->
  <joint name="base_to_chassis" type="fixed">
    <parent link="base_link"/>
    <child link="chassis_link"/>
    <origin rpy="0 0 0" xyz="0 0 0.0375"/>
  </joint>
  <!-- ===================== -->
  <!-- Wheel placement       -->
  <!-- ===================== -->
  <!-- Wheel -->
  <link name="rear_left_wheel_link">
    <inertial>
      <mass value="0.05"/>
      <inertia ixx="3e-5" ixy="0" ixz="0" iyy="3e-5" iyz="0" izz="3e-5"/>
    </inertial>
    <visual>
      <origin rpy="1.5708 0 0"/>
      <geometry>
        <mesh filename="package://ackermann_robot/meshes/wheel_visual.stl" scale="0.001 0.001 0.001"/>
      </geometry>
      <material name="wheel_black"/>
    </visual>
    <collision>
      <origin rpy="1.5708 0 0"/>
      <geometry>
        <cylinder length="0.03" radius="0.0375"/>
      </geometry>
    </collision>
  </link>
  <!-- Gazebo friction for wheels -->
  <gazebo reference="rear_left_wheel_link">
    <mu1>0.8</mu1>
    <mu2>0.8</mu2>
    <kp>1000000.0</kp>
    <kd>100.0</kd>
  </gazebo>
  <joint name="rear_left_wheel_joint" type="continuous">
    <parent link="chassis_link"/>
    <child link="rear_left_wheel_link"/>
    <origin xyz="-0.095 0.076 0.0375"/>
    <axis xyz="0 0 1"/>
    <limit effort="10" velocity="10"/>
  </joint>
  <!-- Wheel -->
  <link name="rear_right_wheel_link">
    <inertial>
      <mass value="0.05"/>
      <inertia ixx="3e-5" ixy="0" ixz="0" iyy="3e-5" iyz="0" izz="3e-5"/>
    </inertial>
    <visual>
      <origin rpy="1.5708 0 0"/>
      <geometry>
        <mesh filename="package://ackermann_robot/meshes/wheel_visual.stl" scale="0.001 0.001 0.001"/>
      </geometry>
      <material name="wheel_black"/>
    </visual>
    <collision>
      <origin rpy="1.5708 0 0"/>
      <geometry>
        <cylinder length="0.03" radius="0.0375"/>
      </geometry>
    </collision>
  </link>
  <!-- Gazebo friction for wheels -->
  <gazebo reference="rear_right_wheel_link">
    <mu1>0.8</mu1>
    <mu2>0.8</mu2>
    <kp>1000000.0</kp>
    <kd>100.0</kd>
  </gazebo>
  <joint name="rear_right_wheel_joint" type="continuous">
    <parent link="chassis_link"/>
    <child link="rear_right_wheel_link"/>
    <origin xyz="-0.095 -0.076 0.0375"/>
    <axis xyz="0 0 1"/>
    <limit effort="10" velocity="10"/>
  </joint>
  <!-- steering knuckle -->
  <link name="front_left_steer_link">
    <inertial>
      <origin xyz="0 0 0"/>
      <mass value="0.01"/>
      <inertia ixx="1e-5" ixy="0" ixz="0" iyy="1e-5" iyz="0" izz="1e-5"/>
    </inertial>
  </link>
  <joint name="front_left_steer_joint" type="revolute">
    <parent link="chassis_link"/>
    <child link="front_left_steer_link"/>
    <origin xyz="0.095 0.076 0.0375"/>
    <axis xyz="0 0 1"/>
    <limit effort="10" lower="-0.6" upper="0.6" velocity="2"/>
  </joint>
  <!-- wheel -->
  <link name="front_left_wheel_link">
    <inertial>
      <mass value="0.05"/>
      <inertia ixx="3e-5" ixy="0" ixz="0" iyy="3e-5" iyz="0" izz="3e-5"/>
    </inertial>
    <visual>
      <origin rpy="1.5708 0 0"/>
      <geometry>
        <!-- <cylinder radius="${wheel_radius}" length="${wheel_width}"/> -->
        <mesh filename="package://ackermann_robot/meshes/wheel_visual.stl" scale="0.001 0.001 0.001"/>
      </geometry>
      <material name="wheel_black"/>
    </visual>
    <collision>
      <origin rpy="1.5708 0 0"/>
      <geometry>
        <cylinder length="0.03" radius="0.0375"/>
      </geometry>
    </collision>
  </link>
  <!-- Gazebo friction for wheels -->
  <gazebo reference="front_left_wheel_link">
    <mu1>0.8</mu1>
    <mu2>0.8</mu2>
    <kp>1000000.0</kp>
    <kd>100.0</kd>
  </gazebo>
  <joint name="front_left_wheel_joint" type="continuous">
    <parent link="front_left_steer_link"/>
    <child link="front_left_wheel_link"/>
    <axis xyz="0 0 1"/>
    <limit effort="10" velocity="10"/>
  </joint>
  <!-- steering knuckle -->
  <link name="front_right_steer_link">
    <inertial>
      <origin xyz="0 0 0"/>
      <mass value="0.01"/>
      <inertia ixx="1e-5" ixy="0" ixz="0" iyy="1e-5" iyz="0" izz="1e-5"/>
    </inertial>
  </link>
  <joint name="front_right_steer_joint" type="revolute">
    <parent link="chassis_link"/>
    <child link="front_right_steer_link"/>
    <origin xyz="0.095 -0.076 0.0375"/>
    <axis xyz="0 0 1"/>
    <limit effort="10" lower="-0.6" upper="0.6" velocity="2"/>
  </joint>
  <!-- wheel -->
  <link name="front_right_wheel_link">
    <inertial>
      <mass value="0.05"/>
      <inertia ixx="3e-5" ixy="0" ixz="0" iyy="3e-5" iyz="0" izz="3e-5"/>
    </inertial>
    <visual>
      <origin rpy="1.5708 0 0"/>
      <geometry>
        <!-- <cylinder radius="${wheel_radius}" length="${wheel_width}"/> -->
        <mesh filename="package://ackermann_robot/meshes/wheel_visual.stl" scale="0.001 0.001 0.001"/>
      </geometry>
      <material name="wheel_black"/>
    </visual>
    <collision>
      <origin rpy="1.5708 0 0"/>
      <geometry>
        <cylinder length="0.03" radius="0.0375"/>
      </geometry>
    </collision>
  </link>
  <!-- Gazebo friction for wheels -->
  <gazebo reference="front_right_wheel_link">
    <mu1>0.8</mu1>
    <mu2>0.8</mu2>
    <kp>1000000.0</kp>
    <kd>100.0</kd>
  </gazebo>
  <joint name="front_right_wheel_joint" type="continuous">
    <parent link="front_right_steer_link"/>
    <child link="front_right_wheel_link"/>
    <axis xyz="0 0 1"/>
    <limit effort="10" velocity="10"/>
  </joint>
  <!-- ===================== -->
  <!-- Gazebo plugins        -->
  <!-- ===================== -->
  <!-- Physics properties for chassis -->
  <gazebo reference="chassis_link">
    <mu1>0.2</mu1>
    <mu2>0.2</mu2>
    <kp>1000000.0</kp>
    <kd>100.0</kd>
  </gazebo>
  <!-- Ackermann steering plugin for Gazebo Jetty -->
  <gazebo>
    <plugin filename="gz-sim-ackermann-steering-system" name="gz::sim::systems::AckermannSteering">
      <front_left_joint>front_left_steer_joint</front_left_joint>
      <front_right_joint>front_right_steer_joint</front_right_joint>
      <rear_left_joint>rear_left_wheel_joint</rear_left_joint>
      <rear_right_joint>rear_right_wheel_joint</rear_right_joint>
      <wheel_base>0.19</wheel_base>
      <wheel_separation>0.152</wheel_separation>
      <wheel_radius>0.0375</wheel_radius>
      <!-- Command input -->
      <topic>/model/ackermann_robot/cmd_vel</topic>
      <!-- ODOMETRY OUTPUT -->
      <odom_topic>/model/ackermann_robot/odometry</odom_topic>
      <odom_frame>odom</odom_frame>
      <base_frame>base_link</base_frame>
      <publish_odom>true</publish_odom>
      <publish_tf>true</publish_tf>
      <odom_publish_freqency>30</odom_publish_freqency>
    </plugin>
  </gazebo>
  <gazebo>
    <plugin filename="gz-sim-joint-state-publisher-system" name="gz::sim::systems::JointStatePublisher"/>
  </gazebo>
</robot>
